Epoch 1 / 10:   0%|                                                                                                                                                                     | 0/250 [00:15<?, ?it/s]
Traceback (most recent call last):
  File "c:\Users\student\Desktop\Transformer Training\.venv\Lib\site-packages\torch\utils\data\dataloader.py", line 1243, in _try_get_data
    data = self._data_queue.get(timeout=timeout)
           ^^^^^^^^^^^^^^^^^^^^^^^^^^^^^^^^^^^^^
  File "C:\Users\student\AppData\Local\Programs\Python\Python311\Lib\multiprocessing\queues.py", line 114, in get
    raise Empty
_queue.Empty

The above exception was the direct cause of the following exception:

Traceback (most recent call last):
  File "C:\Users\student\Desktop\Transformer Training\training.py", line 25, in <module>
    setup_training(data_dir, config)
  File "C:\Users\student\Desktop\Transformer Training\training.py", line 19, in setup_training
    trainer.train(train_loader, val_loader)
  File "C:\Users\student\Desktop\Transformer Training\train.py", line 131, in train
    for batch in progress_bar:
  File "c:\Users\student\Desktop\Transformer Training\.venv\Lib\site-packages\tqdm\std.py", line 1181, in __iter__
    for obj in iterable:
  File "c:\Users\student\Desktop\Transformer Training\.venv\Lib\site-packages\torch\utils\data\dataloader.py", line 701, in __next__
    data = self._next_data()
           ^^^^^^^^^^^^^^^^^
  File "c:\Users\student\Desktop\Transformer Training\.venv\Lib\site-packages\torch\utils\data\dataloader.py", line 1448, in _next_data
    idx, data = self._get_data()
                ^^^^^^^^^^^^^^^^
  File "c:\Users\student\Desktop\Transformer Training\.venv\Lib\site-packages\torch\utils\data\dataloader.py", line 1412, in _get_data
    success, data = self._try_get_data()
                    ^^^^^^^^^^^^^^^^^^^^
  File "c:\Users\student\Desktop\Transformer Training\.venv\Lib\site-packages\torch\utils\data\dataloader.py", line 1256, in _try_get_data
    raise RuntimeError(
RuntimeError: DataLoader worker (pid(s) 16248, 14720) exited unexpectedly
